<?xml version="1.0" ?>
<robot name="BrazoRoboticoURDF">

<material name="silver">
  <color rgba="0.700 0.700 0.700 1.000"/>
</material>

<link name="base_link">
  <inertial>
    <origin xyz="0.0008893073972662583 0.00021210798931074466 0.04271380929485977" rpy="0 0 0"/>
    <mass value="0.09767747102763896"/>
    <inertia ixx="0.00011859266625598709" iyy="0.00012930675855794873" izz="0.00020552422033005992" ixy="-6.150617249923795e-19" iyz="-1.878295560536411e-19" ixz="-1.405895835811561e-06"/>
  </inertial>
  <visual>
    <origin xyz="0 0 0" rpy="0 0 0"/>
    <geometry>
      <mesh filename="meshes/base_link.stl" scale="0.001 0.001 0.001"/>
    </geometry>
    <material name="silver"/>
    <material/>
  </visual>
  <collision>
    <origin xyz="0 0 0" rpy="0 0 0"/>
    <geometry>
      <mesh filename="meshes/base_link.stl" scale="0.001 0.001 0.001"/>
    </geometry>
  </collision>
</link>

<link name="gear_secondary_link1">
  <inertial>
    <origin xyz="0.005321426186839848 -0.002999619351208933 0.0017795703943244146" rpy="0 0 0"/>
    <mass value="0.004200165122561285"/>
    <inertia ixx="1.6392095056707353e-07" iyy="7.11111071326426e-07" izz="5.723911114947696e-07" ixy="2.6508954875507397e-18" iyz="3.7608262858090935e-19" ixz="-7.759531242389493e-08"/>
  </inertial>
  <visual>
    <origin xyz="-0.01145 0.006823 -0.416938" rpy="0 0 0"/>
    <geometry>
      <mesh filename="meshes/gear_secondary_link1.stl" scale="0.001 0.001 0.001"/>
    </geometry>
    <material name="silver"/>
    <material/>
  </visual>
  <collision>
    <origin xyz="-0.01145 0.006823 -0.416938" rpy="0 0 0"/>
    <geometry>
      <mesh filename="meshes/gear_secondary_link1.stl" scale="0.001 0.001 0.001"/>
    </geometry>
  </collision>
</link>

<link name="gripper_grip1">
  <inertial>
    <origin xyz="-0.0045145917957911536 0.0042503806490930066 0.026889522365397933" rpy="0 0 0"/>
    <mass value="0.0057212708857542725"/>
    <inertia ixx="1.6915699793539248e-06" iyy="1.8169224964821682e-06" izz="1.9424615404433212e-07" ixy="6.001757826888752e-19" iyz="-1.8192150124654236e-18" ixz="3.958333743376229e-07"/>
  </inertial>
  <visual>
    <origin xyz="0.041384 0.004823 -0.43346" rpy="0 0 0"/>
    <geometry>
      <mesh filename="meshes/gripper_grip1.stl" scale="0.001 0.001 0.001"/>
    </geometry>
    <material name="silver"/>
    <material/>
  </visual>
  <collision>
    <origin xyz="0.041384 0.004823 -0.43346" rpy="0 0 0"/>
    <geometry>
      <mesh filename="meshes/gripper_grip1.stl" scale="0.001 0.001 0.001"/>
    </geometry>
  </collision>
</link>

<link name="gripper_grip2">
  <inertial>
    <origin xyz="-0.09434084499219159 -0.0005726193514067842 0.43099903762397385" rpy="0 0 0"/>
    <mass value="0.0057212708857542725"/>
    <inertia ixx="1.043180677046075e-06" iyy="1.8169224964826019e-06" izz="8.426354563526038e-07" ixy="3.651029640021255e-18" iyz="4.002230675776569e-18" ixz="-8.409067268810226e-07"/>
  </inertial>
  <visual>
    <origin xyz="-0.152315 0.002 -0.014226" rpy="0 0 0"/>
    <geometry>
      <mesh filename="meshes/gripper_grip2.stl" scale="0.001 0.001 0.001"/>
    </geometry>
    <material name="silver"/>
    <material/>
  </visual>
  <collision>
    <origin xyz="-0.152315 0.002 -0.014226" rpy="0 0 0"/>
    <geometry>
      <mesh filename="meshes/gripper_grip2.stl" scale="0.001 0.001 0.001"/>
    </geometry>
  </collision>
</link>

<link name="rotating_waste1">
  <inertial>
    <origin xyz="-0.00705770673739051 1.079892910212316e-07 0.019422861318638004" rpy="0 0 0"/>
    <mass value="0.09510513374867274"/>
    <inertia ixx="8.190944403390244e-05" iyy="7.095366109407457e-05" izz="7.493756600239466e-05" ixy="6.522312512535723e-18" iyz="4.379414447188909e-17" ixz="8.44605170636769e-06"/>
  </inertial>
  <visual>
    <origin xyz="-0.0 -0.000212 -0.070288" rpy="0 0 0"/>
    <geometry>
      <mesh filename="meshes/rotating_waste1.stl" scale="0.001 0.001 0.001"/>
    </geometry>
    <material name="silver"/>
    <material/>
  </visual>
  <collision>
    <origin xyz="-0.0 -0.000212 -0.070288" rpy="0 0 0"/>
    <geometry>
      <mesh filename="meshes/rotating_waste1.stl" scale="0.001 0.001 0.001"/>
    </geometry>
  </collision>
</link>

<link name="arm_link_11">
  <inertial>
    <origin xyz="0.010308468045322105 4.670098561306761e-07 0.06999625797495565" rpy="0 0 0"/>
    <mass value="0.14626215309797902"/>
    <inertia ixx="0.0004575777848548441" iyy="0.0004376964896299603" izz="3.2685208197066395e-05" ixy="-3.508049124794555e-10" iyz="-1.2264743324115018e-10" ixz="3.569514453954188e-09"/>
  </inertial>
  <visual>
    <origin xyz="0.0025 -0.000212 -0.113838" rpy="0 0 0"/>
    <geometry>
      <mesh filename="meshes/arm_link_11.stl" scale="0.001 0.001 0.001"/>
    </geometry>
    <material name="silver"/>
    <material/>
  </visual>
  <collision>
    <origin xyz="0.0025 -0.000212 -0.113838" rpy="0 0 0"/>
    <geometry>
      <mesh filename="meshes/arm_link_11.stl" scale="0.001 0.001 0.001"/>
    </geometry>
  </collision>
</link>

<link name="arm_link_21">
  <inertial>
    <origin xyz="-0.010578939388045163 -0.00010041868545989852 0.03169882009860353" rpy="0 0 0"/>
    <mass value="0.08515545053956855"/>
    <inertia ixx="0.00012426032120913325" iyy="0.00011079159651151364" izz="2.2532924555524307e-05" ixy="-1.1077281711395749e-08" iyz="2.696372006496918e-07" ixz="8.662942022006617e-07"/>
  </inertial>
  <visual>
    <origin xyz="0.0025 -0.000212 -0.253838" rpy="0 0 0"/>
    <geometry>
      <mesh filename="meshes/arm_link_21.stl" scale="0.001 0.001 0.001"/>
    </geometry>
    <material name="silver"/>
    <material/>
  </visual>
  <collision>
    <origin xyz="0.0025 -0.000212 -0.253838" rpy="0 0 0"/>
    <geometry>
      <mesh filename="meshes/arm_link_21.stl" scale="0.001 0.001 0.001"/>
    </geometry>
  </collision>
</link>

<link name="arm_link1">
  <inertial>
    <origin xyz="0.004102772147760062 3.827723409058348e-05 0.019950471828401095" rpy="0 0 0"/>
    <mass value="0.02167478070167801"/>
    <inertia ixx="6.43838156179008e-06" iyy="5.401058038872249e-06" izz="3.1388642446712567e-06" ixy="3.0886038840326943e-09" iyz="1.204762793740726e-08" ixz="-4.1530274937877766e-07"/>
  </inertial>
  <visual>
    <origin xyz="0.01435 -0.005312 -0.356838" rpy="0 0 0"/>
    <geometry>
      <mesh filename="meshes/arm_link1.stl" scale="0.001 0.001 0.001"/>
    </geometry>
    <material name="silver"/>
    <material/>
  </visual>
  <collision>
    <origin xyz="0.01435 -0.005312 -0.356838" rpy="0 0 0"/>
    <geometry>
      <mesh filename="meshes/arm_link1.stl" scale="0.001 0.001 0.001"/>
    </geometry>
  </collision>
</link>

<link name="gripper_base1">
  <inertial>
    <origin xyz="-0.001604253946628898 -0.004792498235452001 0.02448502523228413" rpy="0 0 0"/>
    <mass value="0.01651044300442688"/>
    <inertia ixx="5.171441786302848e-06" iyy="6.6226823905168875e-06" izz="2.739155774479715e-06" ixy="-1.0643776236590555e-08" iyz="8.806947996832864e-07" ixz="5.789036889611176e-07"/>
  </inertial>
  <visual>
    <origin xyz="-0.0005 -0.005312 -0.386738" rpy="0 0 0"/>
    <geometry>
      <mesh filename="meshes/gripper_base1.stl" scale="0.001 0.001 0.001"/>
    </geometry>
    <material name="silver"/>
    <material/>
  </visual>
  <collision>
    <origin xyz="-0.0005 -0.005312 -0.386738" rpy="0 0 0"/>
    <geometry>
      <mesh filename="meshes/gripper_base1.stl" scale="0.001 0.001 0.001"/>
    </geometry>
  </collision>
</link>

<link name="gear_main_arm1">
  <inertial>
    <origin xyz="-0.005823303291930244 -0.0017433372833794364 0.004361044944136083" rpy="0 0 0"/>
    <mass value="0.0029939593689454966"/>
    <inertia ixx="1.9930602233777638e-07" iyy="5.738981312278322e-07" izz="3.86274967574968e-07" ixy="1.193741907249728e-08" iyz="-7.105233747887034e-09" ixz="1.704973386573922e-07"/>
  </inertial>
  <visual>
    <origin xyz="0.01545 0.006823 -0.416938" rpy="0 0 0"/>
    <geometry>
      <mesh filename="meshes/gear_main_arm1.stl" scale="0.001 0.001 0.001"/>
    </geometry>
    <material name="silver"/>
    <material/>
  </visual>
  <collision>
    <origin xyz="0.01545 0.006823 -0.416938" rpy="0 0 0"/>
    <geometry>
      <mesh filename="meshes/gear_main_arm1.stl" scale="0.001 0.001 0.001"/>
    </geometry>
  </collision>
</link>

<joint name="gripper_joint_3" type="revolute">
  <origin xyz="0.01095 -0.012135 0.0302" rpy="0 0 0"/>
  <parent link="gripper_base1"/>
  <child link="gear_secondary_link1"/>
  <axis xyz="-0.0 -1.0 -0.0"/>
  <limit upper="1.570796" lower="-1.570796" effort="100" velocity="100"/>
</joint>
<transmission name="gripper_joint_3_tran">
  <type>transmission_interface/SimpleTransmission</type>
  <joint name="gripper_joint_3">
    <hardwareInterface>PositionJointInterface</hardwareInterface>
  </joint>
  <actuator name="gripper_joint_3_actr">
    <hardwareInterface>PositionJointInterface</hardwareInterface>
    <mechanicalReduction>1</mechanicalReduction>
  </actuator>
</transmission>

<joint name="gripper_joint_4" type="revolute">
  <origin xyz="-0.025934 0.002 0.016522" rpy="0 0 0"/>
  <parent link="gear_main_arm1"/>
  <child link="gripper_grip1"/>
  <axis xyz="0.0 1.0 0.0"/>
  <limit upper="0.8726" lower="-0.8726" effort="100" velocity="100"/>
</joint>
<transmission name="gripper_joint_4_tran">
  <type>transmission_interface/SimpleTransmission</type>
  <joint name="gripper_joint_4">
    <hardwareInterface>PositionJointInterface</hardwareInterface>
  </joint>
  <actuator name="gripper_joint_4_actr">
    <hardwareInterface>PositionJointInterface</hardwareInterface>
    <mechanicalReduction>1</mechanicalReduction>
  </actuator>
</transmission>

<joint name="gripper_joint_5" type="revolute">
  <origin xyz="0.140865 0.004823 -0.402712" rpy="0 0 0"/>
  <parent link="gear_secondary_link1"/>
  <child link="gripper_grip2"/>
  <axis xyz="-0.0 -1.0 -0.0"/>
  <limit upper="0.8726" lower="-0.8726" effort="100" velocity="100"/>
</joint>
<transmission name="gripper_joint_5_tran">
  <type>transmission_interface/SimpleTransmission</type>
  <joint name="gripper_joint_5">
    <hardwareInterface>PositionJointInterface</hardwareInterface>
  </joint>
  <actuator name="gripper_joint_5_actr">
    <hardwareInterface>PositionJointInterface</hardwareInterface>
    <mechanicalReduction>1</mechanicalReduction>
  </actuator>
</transmission>

<joint name="Revolute_53" type="revolute">
  <origin xyz="0.0 0.000212 0.070288" rpy="0 0 0"/>
  <parent link="base_link"/>
  <child link="rotating_waste1"/>
  <axis xyz="-0.0 -0.0 1.0"/>
  <limit upper="3.141593" lower="-3.141593" effort="100" velocity="100"/>
</joint>
<transmission name="Revolute_53_tran">
  <type>transmission_interface/SimpleTransmission</type>
  <joint name="Revolute_53">
    <hardwareInterface>PositionJointInterface</hardwareInterface>
  </joint>
  <actuator name="Revolute_53_actr">
    <hardwareInterface>PositionJointInterface</hardwareInterface>
    <mechanicalReduction>1</mechanicalReduction>
  </actuator>
</transmission>

<joint name="Revolute_54" type="revolute">
  <origin xyz="-0.0025 0.0 0.04355" rpy="0 0 0"/>
  <parent link="rotating_waste1"/>
  <child link="arm_link_11"/>
  <axis xyz="-1.0 -0.0 -0.0"/>
  <limit upper="1.396263" lower="-1.396263" effort="100" velocity="100"/>
</joint>
<transmission name="Revolute_54_tran">
  <type>transmission_interface/SimpleTransmission</type>
  <joint name="Revolute_54">
    <hardwareInterface>PositionJointInterface</hardwareInterface>
  </joint>
  <actuator name="Revolute_54_actr">
    <hardwareInterface>PositionJointInterface</hardwareInterface>
    <mechanicalReduction>1</mechanicalReduction>
  </actuator>
</transmission>

<joint name="Revolute_55" type="revolute">
  <origin xyz="0.0 0.0 0.14" rpy="0 0 0"/>
  <parent link="arm_link_11"/>
  <child link="arm_link_21"/>
  <axis xyz="-1.0 0.0 -0.0"/>
  <limit upper="1.570796" lower="-1.570796" effort="100" velocity="100"/>
</joint>
<transmission name="Revolute_55_tran">
  <type>transmission_interface/SimpleTransmission</type>
  <joint name="Revolute_55">
    <hardwareInterface>PositionJointInterface</hardwareInterface>
  </joint>
  <actuator name="Revolute_55_actr">
    <hardwareInterface>PositionJointInterface</hardwareInterface>
    <mechanicalReduction>1</mechanicalReduction>
  </actuator>
</transmission>

<joint name="Revolute_56" type="revolute">
  <origin xyz="-0.01185 0.0051 0.103" rpy="0 0 0"/>
  <parent link="arm_link_21"/>
  <child link="arm_link1"/>
  <axis xyz="-0.0 -0.0 1.0"/>
  <limit upper="1.570796" lower="-1.570796" effort="100" velocity="100"/>
</joint>
<transmission name="Revolute_56_tran">
  <type>transmission_interface/SimpleTransmission</type>
  <joint name="Revolute_56">
    <hardwareInterface>PositionJointInterface</hardwareInterface>
  </joint>
  <actuator name="Revolute_56_actr">
    <hardwareInterface>PositionJointInterface</hardwareInterface>
    <mechanicalReduction>1</mechanicalReduction>
  </actuator>
</transmission>

<joint name="Revolute_57" type="revolute">
  <origin xyz="0.01485 0.0 0.0299" rpy="0 0 0"/>
  <parent link="arm_link1"/>
  <child link="gripper_base1"/>
  <axis xyz="-1.0 0.0 -0.0"/>
  <limit upper="1.570796" lower="-1.570796" effort="100" velocity="100"/>
</joint>
<transmission name="Revolute_57_tran">
  <type>transmission_interface/SimpleTransmission</type>
  <joint name="Revolute_57">
    <hardwareInterface>PositionJointInterface</hardwareInterface>
  </joint>
  <actuator name="Revolute_57_actr">
    <hardwareInterface>PositionJointInterface</hardwareInterface>
    <mechanicalReduction>1</mechanicalReduction>
  </actuator>
</transmission>

<joint name="Revolute_58" type="revolute">
  <origin xyz="-0.01595 -0.012135 0.0302" rpy="0 0 0"/>
  <parent link="gripper_base1"/>
  <child link="gear_main_arm1"/>
  <axis xyz="-0.0 -1.0 -0.0"/>
  <limit upper="0.0" lower="-1.396263" effort="100" velocity="100"/>
</joint>
<transmission name="Revolute_58_tran">
  <type>transmission_interface/SimpleTransmission</type>
  <joint name="Revolute_58">
    <hardwareInterface>PositionJointInterface</hardwareInterface>
  </joint>
  <actuator name="Revolute_58_actr">
    <hardwareInterface>PositionJointInterface</hardwareInterface>
    <mechanicalReduction>1</mechanicalReduction>
  </actuator>
</transmission>

</robot>
